[15/01/2023 18:16:00] [INFO    ] discord.gateway: Shard ID None has connected to Gateway (Session ID: ea528b0bee8725aced812d9cfda23e73).
[15/01/2023 18:18:34] [WARNING ] discord.ext.commands.bot: Privileged message content intent is missing, commands may not work as expected.
[15/01/2023 18:18:34] [INFO    ] discord.client: logging in using static token
[15/01/2023 18:18:45] [INFO    ] discord.gateway: Shard ID None has connected to Gateway (Session ID: 5fdb4edabe42a84492a633c392d1946e).
[15/01/2023 18:18:51] [ERROR   ] discord.app_commands.tree: Ignoring exception in command 'create'
Traceback (most recent call last):
  File "C:\Users\avart\AppData\Local\Programs\Python\Python38\lib\site-packages\discord\app_commands\commands.py", line 861, in _do_call
    return await self._callback(self.binding, interaction, **params)  # type: ignore
  File "C:\Users\avart\OneDrive\Máy tính\remind_bot\bot\cogs\server\channel.py", line 40, in _create
    find = await self.db.find({"onwerID" : member.id, "guildID" : guild.id})
  File "C:\Users\avart\OneDrive\Máy tính\remind_bot\bot\ultils\db_action.py", line 30, in find
    return json.loads(pprint.pformat(i))
  File "C:\Users\avart\AppData\Local\Programs\Python\Python38\lib\json\__init__.py", line 357, in loads
    return _default_decoder.decode(s)
  File "C:\Users\avart\AppData\Local\Programs\Python\Python38\lib\json\decoder.py", line 337, in decode
    obj, end = self.raw_decode(s, idx=_w(s, 0).end())
  File "C:\Users\avart\AppData\Local\Programs\Python\Python38\lib\json\decoder.py", line 353, in raw_decode
    obj, end = self.scan_once(s, idx)
json.decoder.JSONDecodeError: Expecting property name enclosed in double quotes: line 1 column 2 (char 1)

The above exception was the direct cause of the following exception:

Traceback (most recent call last):
  File "C:\Users\avart\AppData\Local\Programs\Python\Python38\lib\site-packages\discord\app_commands\tree.py", line 1242, in _call
    await command._invoke_with_namespace(interaction, namespace)
  File "C:\Users\avart\AppData\Local\Programs\Python\Python38\lib\site-packages\discord\app_commands\commands.py", line 887, in _invoke_with_namespace
    return await self._do_call(interaction, transformed_values)
  File "C:\Users\avart\AppData\Local\Programs\Python\Python38\lib\site-packages\discord\app_commands\commands.py", line 880, in _do_call
    raise CommandInvokeError(self, e) from e
discord.app_commands.errors.CommandInvokeError: Command 'create' raised an exception: JSONDecodeError: Expecting property name enclosed in double quotes: line 1 column 2 (char 1)
[15/01/2023 18:20:27] [WARNING ] discord.ext.commands.bot: Privileged message content intent is missing, commands may not work as expected.
[15/01/2023 18:20:27] [INFO    ] discord.client: logging in using static token
[15/01/2023 18:20:39] [INFO    ] discord.gateway: Shard ID None has connected to Gateway (Session ID: aea84357002ab752332a7752f2603f9a).
[15/01/2023 18:20:50] [ERROR   ] discord.app_commands.tree: Ignoring exception in command 'create'
Traceback (most recent call last):
  File "C:\Users\avart\AppData\Local\Programs\Python\Python38\lib\site-packages\discord\app_commands\commands.py", line 861, in _do_call
    return await self._callback(self.binding, interaction, **params)  # type: ignore
  File "C:\Users\avart\OneDrive\Máy tính\remind_bot\bot\cogs\server\channel.py", line 43, in _create
    data = loads(find)
  File "C:\Users\avart\AppData\Local\Programs\Python\Python38\lib\json\__init__.py", line 357, in loads
    return _default_decoder.decode(s)
  File "C:\Users\avart\AppData\Local\Programs\Python\Python38\lib\json\decoder.py", line 337, in decode
    obj, end = self.raw_decode(s, idx=_w(s, 0).end())
  File "C:\Users\avart\AppData\Local\Programs\Python\Python38\lib\json\decoder.py", line 353, in raw_decode
    obj, end = self.scan_once(s, idx)
json.decoder.JSONDecodeError: Expecting property name enclosed in double quotes: line 1 column 2 (char 1)

The above exception was the direct cause of the following exception:

Traceback (most recent call last):
  File "C:\Users\avart\AppData\Local\Programs\Python\Python38\lib\site-packages\discord\app_commands\tree.py", line 1242, in _call
    await command._invoke_with_namespace(interaction, namespace)
  File "C:\Users\avart\AppData\Local\Programs\Python\Python38\lib\site-packages\discord\app_commands\commands.py", line 887, in _invoke_with_namespace
    return await self._do_call(interaction, transformed_values)
  File "C:\Users\avart\AppData\Local\Programs\Python\Python38\lib\site-packages\discord\app_commands\commands.py", line 880, in _do_call
    raise CommandInvokeError(self, e) from e
discord.app_commands.errors.CommandInvokeError: Command 'create' raised an exception: JSONDecodeError: Expecting property name enclosed in double quotes: line 1 column 2 (char 1)
[15/01/2023 18:21:31] [WARNING ] discord.ext.commands.bot: Privileged message content intent is missing, commands may not work as expected.
[15/01/2023 18:21:31] [INFO    ] discord.client: logging in using static token
[15/01/2023 18:21:41] [INFO    ] discord.gateway: Shard ID None has connected to Gateway (Session ID: b06589f2f4a1901d7b6d80585fcfa658).
[15/01/2023 18:22:59] [WARNING ] discord.ext.commands.bot: Privileged message content intent is missing, commands may not work as expected.
[15/01/2023 18:22:59] [INFO    ] discord.client: logging in using static token
[15/01/2023 18:23:10] [INFO    ] discord.gateway: Shard ID None has connected to Gateway (Session ID: 7a44e06d9a765a94078952a6d7127024).
[15/01/2023 18:23:45] [ERROR   ] discord.app_commands.tree: Ignoring exception in command 'create'
Traceback (most recent call last):
  File "C:\Users\avart\AppData\Local\Programs\Python\Python38\lib\site-packages\discord\app_commands\commands.py", line 861, in _do_call
    return await self._callback(self.binding, interaction, **params)  # type: ignore
  File "C:\Users\avart\OneDrive\Máy tính\remind_bot\bot\cogs\server\channel.py", line 43, in _create
    print(dict(find))
ValueError: dictionary update sequence element #0 has length 1; 2 is required

The above exception was the direct cause of the following exception:

Traceback (most recent call last):
  File "C:\Users\avart\AppData\Local\Programs\Python\Python38\lib\site-packages\discord\app_commands\tree.py", line 1242, in _call
    await command._invoke_with_namespace(interaction, namespace)
  File "C:\Users\avart\AppData\Local\Programs\Python\Python38\lib\site-packages\discord\app_commands\commands.py", line 887, in _invoke_with_namespace
    return await self._do_call(interaction, transformed_values)
  File "C:\Users\avart\AppData\Local\Programs\Python\Python38\lib\site-packages\discord\app_commands\commands.py", line 880, in _do_call
    raise CommandInvokeError(self, e) from e
discord.app_commands.errors.CommandInvokeError: Command 'create' raised an exception: ValueError: dictionary update sequence element #0 has length 1; 2 is required
[15/01/2023 18:25:13] [WARNING ] discord.ext.commands.bot: Privileged message content intent is missing, commands may not work as expected.
[15/01/2023 18:25:13] [INFO    ] discord.client: logging in using static token
[15/01/2023 18:25:24] [INFO    ] discord.gateway: Shard ID None has connected to Gateway (Session ID: 0e14486e8a3064f8cafc7cffa3280252).
[15/01/2023 18:26:48] [ERROR   ] discord.app_commands.tree: Ignoring exception in command 'create'
Traceback (most recent call last):
  File "C:\Users\avart\AppData\Local\Programs\Python\Python38\lib\site-packages\discord\app_commands\commands.py", line 861, in _do_call
    return await self._callback(self.binding, interaction, **params)  # type: ignore
  File "C:\Users\avart\OneDrive\Máy tính\remind_bot\bot\cogs\server\channel.py", line 44, in _create
    data = loads(data)
  File "C:\Users\avart\AppData\Local\Programs\Python\Python38\lib\json\__init__.py", line 357, in loads
    return _default_decoder.decode(s)
  File "C:\Users\avart\AppData\Local\Programs\Python\Python38\lib\json\decoder.py", line 337, in decode
    obj, end = self.raw_decode(s, idx=_w(s, 0).end())
  File "C:\Users\avart\AppData\Local\Programs\Python\Python38\lib\json\decoder.py", line 353, in raw_decode
    obj, end = self.scan_once(s, idx)
json.decoder.JSONDecodeError: Expecting property name enclosed in double quotes: line 1 column 2 (char 1)

The above exception was the direct cause of the following exception:

Traceback (most recent call last):
  File "C:\Users\avart\AppData\Local\Programs\Python\Python38\lib\site-packages\discord\app_commands\tree.py", line 1242, in _call
    await command._invoke_with_namespace(interaction, namespace)
  File "C:\Users\avart\AppData\Local\Programs\Python\Python38\lib\site-packages\discord\app_commands\commands.py", line 887, in _invoke_with_namespace
    return await self._do_call(interaction, transformed_values)
  File "C:\Users\avart\AppData\Local\Programs\Python\Python38\lib\site-packages\discord\app_commands\commands.py", line 880, in _do_call
    raise CommandInvokeError(self, e) from e
discord.app_commands.errors.CommandInvokeError: Command 'create' raised an exception: JSONDecodeError: Expecting property name enclosed in double quotes: line 1 column 2 (char 1)
[15/01/2023 18:40:16] [WARNING ] discord.ext.commands.bot: Privileged message content intent is missing, commands may not work as expected.
[15/01/2023 18:40:16] [INFO    ] discord.client: logging in using static token
[15/01/2023 18:40:27] [INFO    ] discord.gateway: Shard ID None has connected to Gateway (Session ID: e0382c5c01721631f140ebbcb22ea8cc).
[15/01/2023 18:43:34] [ERROR   ] discord.app_commands.tree: Ignoring exception in command 'add_user'
Traceback (most recent call last):
  File "C:\Users\avart\AppData\Local\Programs\Python\Python38\lib\site-packages\discord\app_commands\commands.py", line 861, in _do_call
    return await self._callback(self.binding, interaction, **params)  # type: ignore
  File "C:\Users\avart\OneDrive\Máy tính\remind_bot\bot\cogs\server\channel.py", line 69, in _add_user
    return await interaction.followup.send(f"Bạn không phải chủ phòng này")
  File "C:\Users\avart\AppData\Local\Programs\Python\Python38\lib\site-packages\discord\webhook\async_.py", line 1726, in send
    data = await adapter.execute_webhook(
  File "C:\Users\avart\AppData\Local\Programs\Python\Python38\lib\site-packages\discord\webhook\async_.py", line 218, in request
    raise NotFound(response, data)
discord.errors.NotFound: 404 Not Found (error code: 10015): Unknown Webhook

The above exception was the direct cause of the following exception:

Traceback (most recent call last):
  File "C:\Users\avart\AppData\Local\Programs\Python\Python38\lib\site-packages\discord\app_commands\tree.py", line 1242, in _call
    await command._invoke_with_namespace(interaction, namespace)
  File "C:\Users\avart\AppData\Local\Programs\Python\Python38\lib\site-packages\discord\app_commands\commands.py", line 887, in _invoke_with_namespace
    return await self._do_call(interaction, transformed_values)
  File "C:\Users\avart\AppData\Local\Programs\Python\Python38\lib\site-packages\discord\app_commands\commands.py", line 880, in _do_call
    raise CommandInvokeError(self, e) from e
discord.app_commands.errors.CommandInvokeError: Command 'add_user' raised an exception: NotFound: 404 Not Found (error code: 10015): Unknown Webhook
[15/01/2023 18:44:36] [ERROR   ] discord.app_commands.tree: Ignoring exception in command 'add_user'
Traceback (most recent call last):
  File "C:\Users\avart\AppData\Local\Programs\Python\Python38\lib\site-packages\discord\app_commands\commands.py", line 861, in _do_call
    return await self._callback(self.binding, interaction, **params)  # type: ignore
  File "C:\Users\avart\OneDrive\Máy tính\remind_bot\bot\cogs\server\channel.py", line 69, in _add_user
    return await interaction.response.send_message(f"Bạn không phải chủ phòng này")
  File "C:\Users\avart\AppData\Local\Programs\Python\Python38\lib\site-packages\discord\webhook\async_.py", line 1726, in send
    data = await adapter.execute_webhook(
  File "C:\Users\avart\AppData\Local\Programs\Python\Python38\lib\site-packages\discord\webhook\async_.py", line 218, in request
    raise NotFound(response, data)
discord.errors.NotFound: 404 Not Found (error code: 10015): Unknown Webhook

The above exception was the direct cause of the following exception:

Traceback (most recent call last):
  File "C:\Users\avart\AppData\Local\Programs\Python\Python38\lib\site-packages\discord\app_commands\tree.py", line 1242, in _call
    await command._invoke_with_namespace(interaction, namespace)
  File "C:\Users\avart\AppData\Local\Programs\Python\Python38\lib\site-packages\discord\app_commands\commands.py", line 887, in _invoke_with_namespace
    return await self._do_call(interaction, transformed_values)
  File "C:\Users\avart\AppData\Local\Programs\Python\Python38\lib\site-packages\discord\app_commands\commands.py", line 880, in _do_call
    raise CommandInvokeError(self, e) from e
discord.app_commands.errors.CommandInvokeError: Command 'add_user' raised an exception: NotFound: 404 Not Found (error code: 10015): Unknown Webhook
[15/01/2023 18:45:02] [WARNING ] discord.ext.commands.bot: Privileged message content intent is missing, commands may not work as expected.
[15/01/2023 18:45:02] [INFO    ] discord.client: logging in using static token
[15/01/2023 18:45:13] [INFO    ] discord.gateway: Shard ID None has connected to Gateway (Session ID: 36d965350225541d0e606a2190048ca4).
[15/01/2023 18:49:54] [WARNING ] discord.ext.commands.bot: Privileged message content intent is missing, commands may not work as expected.
[15/01/2023 18:49:54] [INFO    ] discord.client: logging in using static token
[15/01/2023 18:50:07] [INFO    ] discord.gateway: Shard ID None has connected to Gateway (Session ID: 22ce99ec3911264380d944cbd0e8d789).
[15/01/2023 18:52:22] [WARNING ] discord.ext.commands.bot: Privileged message content intent is missing, commands may not work as expected.
[15/01/2023 18:52:22] [INFO    ] discord.client: logging in using static token
[15/01/2023 18:52:34] [INFO    ] discord.gateway: Shard ID None has connected to Gateway (Session ID: 0d8436bc2d94c1595024eb92f0e86509).
[15/01/2023 19:18:29] [WARNING ] discord.ext.commands.bot: Privileged message content intent is missing, commands may not work as expected.
[15/01/2023 19:18:29] [INFO    ] discord.client: logging in using static token
[15/01/2023 19:18:35] [INFO    ] discord.gateway: Shard ID None has connected to Gateway (Session ID: 21af2e66af7e312c24a5610bdf97795a).
[15/01/2023 19:31:45] [WARNING ] discord.ext.commands.bot: Privileged message content intent is missing, commands may not work as expected.
[15/01/2023 19:31:45] [INFO    ] discord.client: logging in using static token
[15/01/2023 19:31:51] [INFO    ] discord.gateway: Shard ID None has connected to Gateway (Session ID: fc3ac5bda10270e15f2ca6ab1940d13f).
[15/01/2023 19:34:40] [WARNING ] discord.ext.commands.bot: Privileged message content intent is missing, commands may not work as expected.
[15/01/2023 19:34:40] [INFO    ] discord.client: logging in using static token
[15/01/2023 19:34:47] [INFO    ] discord.gateway: Shard ID None has connected to Gateway (Session ID: 147ede5c2170e31a6c24722f8e31ae88).
[15/01/2023 19:38:20] [WARNING ] discord.ext.commands.bot: Privileged message content intent is missing, commands may not work as expected.
[15/01/2023 19:38:20] [INFO    ] discord.client: logging in using static token
[15/01/2023 19:38:28] [INFO    ] discord.gateway: Shard ID None has connected to Gateway (Session ID: 99c34e8d442c377c9d49901bf700b81f).
[15/01/2023 19:39:54] [WARNING ] discord.ext.commands.bot: Privileged message content intent is missing, commands may not work as expected.
[15/01/2023 19:39:54] [INFO    ] discord.client: logging in using static token
[15/01/2023 19:40:00] [INFO    ] discord.gateway: Shard ID None has connected to Gateway (Session ID: 8ad9967422c6de45f4df4bd2fe861028).
[15/01/2023 19:40:37] [WARNING ] discord.ext.commands.bot: Privileged message content intent is missing, commands may not work as expected.
[15/01/2023 19:40:37] [INFO    ] discord.client: logging in using static token
[15/01/2023 19:40:44] [INFO    ] discord.gateway: Shard ID None has connected to Gateway (Session ID: b29dc2218ee02cc5ea667bcdee1ba775).
[15/01/2023 19:49:58] [INFO    ] discord.client: logging in using static token
[15/01/2023 19:50:06] [INFO    ] discord.gateway: Shard ID None has connected to Gateway (Session ID: 39103dc41fe9df9edfa318f11f0a3f76).
[15/01/2023 20:16:36] [INFO    ] discord.client: logging in using static token
[15/01/2023 20:16:42] [INFO    ] discord.gateway: Shard ID None has connected to Gateway (Session ID: 8611f855434df02afb8f67172509c2e3).
[15/01/2023 20:18:36] [INFO    ] discord.client: logging in using static token
[15/01/2023 20:18:43] [INFO    ] discord.gateway: Shard ID None has connected to Gateway (Session ID: 8be3797bc47c39fd459a2bbaef035875).
[15/01/2023 20:19:37] [INFO    ] discord.client: logging in using static token
[15/01/2023 20:19:44] [INFO    ] discord.gateway: Shard ID None has connected to Gateway (Session ID: 74df75301ffdfd020b82e55f5e94d56a).
[15/01/2023 20:25:56] [ERROR   ] discord.client: Attempting a reconnect in 0.26s
Traceback (most recent call last):
  File "C:\Users\avart\AppData\Local\Programs\Python\Python38\lib\site-packages\aiohttp\connector.py", line 999, in _create_direct_connection
    hosts = await asyncio.shield(host_resolved)
  File "C:\Users\avart\AppData\Local\Programs\Python\Python38\lib\site-packages\aiohttp\connector.py", line 865, in _resolve_host
    addrs = await self._resolver.resolve(host, port, family=self._family)
  File "C:\Users\avart\AppData\Local\Programs\Python\Python38\lib\site-packages\aiohttp\resolver.py", line 31, in resolve
    infos = await self._loop.getaddrinfo(
  File "C:\Users\avart\AppData\Local\Programs\Python\Python38\lib\asyncio\base_events.py", line 825, in getaddrinfo
    return await self.run_in_executor(
  File "C:\Users\avart\AppData\Local\Programs\Python\Python38\lib\concurrent\futures\thread.py", line 57, in run
    result = self.fn(*self.args, **self.kwargs)
  File "C:\Users\avart\AppData\Local\Programs\Python\Python38\lib\socket.py", line 918, in getaddrinfo
    for res in _socket.getaddrinfo(host, port, family, type, proto, flags):
socket.gaierror: [Errno 11001] getaddrinfo failed

The above exception was the direct cause of the following exception:

Traceback (most recent call last):
  File "C:\Users\avart\AppData\Local\Programs\Python\Python38\lib\site-packages\discord\client.py", line 624, in connect
    self.ws = await asyncio.wait_for(coro, timeout=60.0)
  File "C:\Users\avart\AppData\Local\Programs\Python\Python38\lib\asyncio\tasks.py", line 494, in wait_for
    return fut.result()
  File "C:\Users\avart\AppData\Local\Programs\Python\Python38\lib\site-packages\discord\gateway.py", line 372, in from_client
    socket = await client.http.ws_connect(str(url))
  File "C:\Users\avart\AppData\Local\Programs\Python\Python38\lib\site-packages\discord\http.py", line 536, in ws_connect
    return await self.__session.ws_connect(url, **kwargs)
  File "C:\Users\avart\AppData\Local\Programs\Python\Python38\lib\site-packages\aiohttp\client.py", line 754, in _ws_connect
    resp = await self.request(
  File "C:\Users\avart\AppData\Local\Programs\Python\Python38\lib\site-packages\aiohttp\client.py", line 520, in _request
    conn = await self._connector.connect(
  File "C:\Users\avart\AppData\Local\Programs\Python\Python38\lib\site-packages\aiohttp\connector.py", line 535, in connect
    proto = await self._create_connection(req, traces, timeout)
  File "C:\Users\avart\AppData\Local\Programs\Python\Python38\lib\site-packages\aiohttp\connector.py", line 892, in _create_connection
    _, proto = await self._create_direct_connection(req, traces, timeout)
  File "C:\Users\avart\AppData\Local\Programs\Python\Python38\lib\site-packages\aiohttp\connector.py", line 1011, in _create_direct_connection
    raise ClientConnectorError(req.connection_key, exc) from exc
aiohttp.client_exceptions.ClientConnectorError: Cannot connect to host gateway-us-east1-d.discord.gg:443 ssl:default [getaddrinfo failed]
[15/01/2023 20:25:56] [ERROR   ] discord.client: Attempting a reconnect in 2.86s
Traceback (most recent call last):
  File "C:\Users\avart\AppData\Local\Programs\Python\Python38\lib\site-packages\aiohttp\connector.py", line 999, in _create_direct_connection
    hosts = await asyncio.shield(host_resolved)
  File "C:\Users\avart\AppData\Local\Programs\Python\Python38\lib\site-packages\aiohttp\connector.py", line 865, in _resolve_host
    addrs = await self._resolver.resolve(host, port, family=self._family)
  File "C:\Users\avart\AppData\Local\Programs\Python\Python38\lib\site-packages\aiohttp\resolver.py", line 31, in resolve
    infos = await self._loop.getaddrinfo(
  File "C:\Users\avart\AppData\Local\Programs\Python\Python38\lib\asyncio\base_events.py", line 825, in getaddrinfo
    return await self.run_in_executor(
  File "C:\Users\avart\AppData\Local\Programs\Python\Python38\lib\concurrent\futures\thread.py", line 57, in run
    result = self.fn(*self.args, **self.kwargs)
  File "C:\Users\avart\AppData\Local\Programs\Python\Python38\lib\socket.py", line 918, in getaddrinfo
    for res in _socket.getaddrinfo(host, port, family, type, proto, flags):
socket.gaierror: [Errno 11001] getaddrinfo failed

The above exception was the direct cause of the following exception:

Traceback (most recent call last):
  File "C:\Users\avart\AppData\Local\Programs\Python\Python38\lib\site-packages\discord\client.py", line 624, in connect
    self.ws = await asyncio.wait_for(coro, timeout=60.0)
  File "C:\Users\avart\AppData\Local\Programs\Python\Python38\lib\asyncio\tasks.py", line 494, in wait_for
    return fut.result()
  File "C:\Users\avart\AppData\Local\Programs\Python\Python38\lib\site-packages\discord\gateway.py", line 372, in from_client
    socket = await client.http.ws_connect(str(url))
  File "C:\Users\avart\AppData\Local\Programs\Python\Python38\lib\site-packages\discord\http.py", line 536, in ws_connect
    return await self.__session.ws_connect(url, **kwargs)
  File "C:\Users\avart\AppData\Local\Programs\Python\Python38\lib\site-packages\aiohttp\client.py", line 754, in _ws_connect
    resp = await self.request(
  File "C:\Users\avart\AppData\Local\Programs\Python\Python38\lib\site-packages\aiohttp\client.py", line 520, in _request
    conn = await self._connector.connect(
  File "C:\Users\avart\AppData\Local\Programs\Python\Python38\lib\site-packages\aiohttp\connector.py", line 535, in connect
    proto = await self._create_connection(req, traces, timeout)
  File "C:\Users\avart\AppData\Local\Programs\Python\Python38\lib\site-packages\aiohttp\connector.py", line 892, in _create_connection
    _, proto = await self._create_direct_connection(req, traces, timeout)
  File "C:\Users\avart\AppData\Local\Programs\Python\Python38\lib\site-packages\aiohttp\connector.py", line 1011, in _create_direct_connection
    raise ClientConnectorError(req.connection_key, exc) from exc
aiohttp.client_exceptions.ClientConnectorError: Cannot connect to host gateway-us-east1-d.discord.gg:443 ssl:default [getaddrinfo failed]
[15/01/2023 20:36:53] [ERROR   ] discord.client: Attempting a reconnect in 6.77s
Traceback (most recent call last):
  File "C:\Users\avart\AppData\Local\Programs\Python\Python38\lib\site-packages\aiohttp\connector.py", line 999, in _create_direct_connection
    hosts = await asyncio.shield(host_resolved)
  File "C:\Users\avart\AppData\Local\Programs\Python\Python38\lib\site-packages\aiohttp\connector.py", line 865, in _resolve_host
    addrs = await self._resolver.resolve(host, port, family=self._family)
  File "C:\Users\avart\AppData\Local\Programs\Python\Python38\lib\site-packages\aiohttp\resolver.py", line 31, in resolve
    infos = await self._loop.getaddrinfo(
  File "C:\Users\avart\AppData\Local\Programs\Python\Python38\lib\asyncio\base_events.py", line 825, in getaddrinfo
    return await self.run_in_executor(
  File "C:\Users\avart\AppData\Local\Programs\Python\Python38\lib\concurrent\futures\thread.py", line 57, in run
    result = self.fn(*self.args, **self.kwargs)
  File "C:\Users\avart\AppData\Local\Programs\Python\Python38\lib\socket.py", line 918, in getaddrinfo
    for res in _socket.getaddrinfo(host, port, family, type, proto, flags):
socket.gaierror: [Errno 11001] getaddrinfo failed

The above exception was the direct cause of the following exception:

Traceback (most recent call last):
  File "C:\Users\avart\AppData\Local\Programs\Python\Python38\lib\site-packages\discord\client.py", line 624, in connect
    self.ws = await asyncio.wait_for(coro, timeout=60.0)
  File "C:\Users\avart\AppData\Local\Programs\Python\Python38\lib\asyncio\tasks.py", line 494, in wait_for
    return fut.result()
  File "C:\Users\avart\AppData\Local\Programs\Python\Python38\lib\site-packages\discord\gateway.py", line 372, in from_client
    socket = await client.http.ws_connect(str(url))
  File "C:\Users\avart\AppData\Local\Programs\Python\Python38\lib\site-packages\discord\http.py", line 536, in ws_connect
    return await self.__session.ws_connect(url, **kwargs)
  File "C:\Users\avart\AppData\Local\Programs\Python\Python38\lib\site-packages\aiohttp\client.py", line 754, in _ws_connect
    resp = await self.request(
  File "C:\Users\avart\AppData\Local\Programs\Python\Python38\lib\site-packages\aiohttp\client.py", line 520, in _request
    conn = await self._connector.connect(
  File "C:\Users\avart\AppData\Local\Programs\Python\Python38\lib\site-packages\aiohttp\connector.py", line 535, in connect
    proto = await self._create_connection(req, traces, timeout)
  File "C:\Users\avart\AppData\Local\Programs\Python\Python38\lib\site-packages\aiohttp\connector.py", line 892, in _create_connection
    _, proto = await self._create_direct_connection(req, traces, timeout)
  File "C:\Users\avart\AppData\Local\Programs\Python\Python38\lib\site-packages\aiohttp\connector.py", line 1011, in _create_direct_connection
    raise ClientConnectorError(req.connection_key, exc) from exc
aiohttp.client_exceptions.ClientConnectorError: Cannot connect to host gateway-us-east1-d.discord.gg:443 ssl:default [getaddrinfo failed]
[15/01/2023 20:37:00] [ERROR   ] discord.client: Attempting a reconnect in 10.12s
Traceback (most recent call last):
  File "C:\Users\avart\AppData\Local\Programs\Python\Python38\lib\site-packages\aiohttp\connector.py", line 999, in _create_direct_connection
    hosts = await asyncio.shield(host_resolved)
  File "C:\Users\avart\AppData\Local\Programs\Python\Python38\lib\site-packages\aiohttp\connector.py", line 865, in _resolve_host
    addrs = await self._resolver.resolve(host, port, family=self._family)
  File "C:\Users\avart\AppData\Local\Programs\Python\Python38\lib\site-packages\aiohttp\resolver.py", line 31, in resolve
    infos = await self._loop.getaddrinfo(
  File "C:\Users\avart\AppData\Local\Programs\Python\Python38\lib\asyncio\base_events.py", line 825, in getaddrinfo
    return await self.run_in_executor(
  File "C:\Users\avart\AppData\Local\Programs\Python\Python38\lib\concurrent\futures\thread.py", line 57, in run
    result = self.fn(*self.args, **self.kwargs)
  File "C:\Users\avart\AppData\Local\Programs\Python\Python38\lib\socket.py", line 918, in getaddrinfo
    for res in _socket.getaddrinfo(host, port, family, type, proto, flags):
socket.gaierror: [Errno 11001] getaddrinfo failed

The above exception was the direct cause of the following exception:

Traceback (most recent call last):
  File "C:\Users\avart\AppData\Local\Programs\Python\Python38\lib\site-packages\discord\client.py", line 624, in connect
    self.ws = await asyncio.wait_for(coro, timeout=60.0)
  File "C:\Users\avart\AppData\Local\Programs\Python\Python38\lib\asyncio\tasks.py", line 494, in wait_for
    return fut.result()
  File "C:\Users\avart\AppData\Local\Programs\Python\Python38\lib\site-packages\discord\gateway.py", line 372, in from_client
    socket = await client.http.ws_connect(str(url))
  File "C:\Users\avart\AppData\Local\Programs\Python\Python38\lib\site-packages\discord\http.py", line 536, in ws_connect
    return await self.__session.ws_connect(url, **kwargs)
  File "C:\Users\avart\AppData\Local\Programs\Python\Python38\lib\site-packages\aiohttp\client.py", line 754, in _ws_connect
    resp = await self.request(
  File "C:\Users\avart\AppData\Local\Programs\Python\Python38\lib\site-packages\aiohttp\client.py", line 520, in _request
    conn = await self._connector.connect(
  File "C:\Users\avart\AppData\Local\Programs\Python\Python38\lib\site-packages\aiohttp\connector.py", line 535, in connect
    proto = await self._create_connection(req, traces, timeout)
  File "C:\Users\avart\AppData\Local\Programs\Python\Python38\lib\site-packages\aiohttp\connector.py", line 892, in _create_connection
    _, proto = await self._create_direct_connection(req, traces, timeout)
  File "C:\Users\avart\AppData\Local\Programs\Python\Python38\lib\site-packages\aiohttp\connector.py", line 1011, in _create_direct_connection
    raise ClientConnectorError(req.connection_key, exc) from exc
aiohttp.client_exceptions.ClientConnectorError: Cannot connect to host gateway-us-east1-d.discord.gg:443 ssl:default [getaddrinfo failed]
[15/01/2023 20:37:11] [INFO    ] discord.gateway: Shard ID None session has been invalidated.
[15/01/2023 20:37:18] [INFO    ] discord.gateway: Shard ID None has connected to Gateway (Session ID: 01a5ab684ff2572b1a27531cdaccedbd).
[15/01/2023 20:38:16] [INFO    ] discord.client: logging in using static token
[15/01/2023 20:38:23] [INFO    ] discord.gateway: Shard ID None has connected to Gateway (Session ID: 913806e0c89e4f55cd21a305ec54edad).
[15/01/2023 20:58:47] [INFO    ] discord.client: logging in using static token
[15/01/2023 20:58:54] [INFO    ] discord.gateway: Shard ID None has connected to Gateway (Session ID: b687b9a111906116b573f66ef0704f63).
[15/01/2023 20:59:24] [INFO    ] discord.client: logging in using static token
[15/01/2023 20:59:33] [INFO    ] discord.gateway: Shard ID None has connected to Gateway (Session ID: c2e95be38955b91a6bd3bc215f2a54e7).
[15/01/2023 21:00:24] [INFO    ] discord.client: logging in using static token
[15/01/2023 21:00:32] [INFO    ] discord.gateway: Shard ID None has connected to Gateway (Session ID: 9da32334e02cfcf9260c0f90529354b4).
[15/01/2023 21:01:15] [INFO    ] discord.client: logging in using static token
[15/01/2023 21:01:23] [INFO    ] discord.gateway: Shard ID None has connected to Gateway (Session ID: 6092726c55e1b18bc18516eae0ce5c92).
[15/01/2023 21:02:46] [INFO    ] discord.client: logging in using static token
[15/01/2023 21:02:53] [INFO    ] discord.gateway: Shard ID None has connected to Gateway (Session ID: 7af0c189a3aaa367a8e7e117834e75c4).
